Workbook

Sheet Dasboard
A15: Total Revenue (FY Till Date) | B15: =SUM(Customer_Tiers[Total_Sales]) -> 57256968
A16: Total Customers | B16: =COUNTA(Customer_Tiers[Customer]) -> 1476
A17: Active Customers | B17: =COUNTIF(Customer_Tiers[Activity Status],"Active") -> 425
A18: Inactive Customers | B18: =COUNTIF(Customer_Tiers[Activity Status],"Inactive") -> 739
A19: At Risk Customers | B19: =COUNTIF(Customer_Tiers[Activity Status],"At Risk") -> 261
A20: Average
A25: Top 10 Revenue | B25: =SUM(INDEX(Customer_Tiers[Total_Sales],1):INDEX(Customer_Tiers[Total_Sales],10)) -> 12881389 | C25: =B25/SUM(Customer_Tiers[Total_Sales]) -> 0.22497504
A26: Top 50 Revenue | B26: =SUM(INDEX(Customer_Tiers[Total_Sales],1):INDEX(Customer_Tiers[Total_Sales],50)) -> 27110974 | C26: =B26/SUM(Customer_Tiers[Total_Sales]) -> 0.4734965
A27: Platinum Revenue % | B27: =SUMIFS(Customer_Tiers[Total_Sales], Customer_Tiers[Tier],"Platinum") -> 10342205
A28: Gold Revenue % | B28: =SUMIFS(Customer_Tiers[Total_Sales], Customer_Tiers[Tier],"Gold") -> 5612534
A34: Platinum Inactive Count | B34: =COUNTIFS(Customer_Tiers[Tier],"Platinum",Customer_Tiers[Activity Status],"Inactive") -> 0
A35: Platinum At Risk | B35: =COUNTIFS(Customer_Tiers[Tier],"Platinum",Customer_Tiers[Activity Status],"At Risk") -> 1
A36: Gold Inactivity Count | B36: =COUNTIFS(Customer_Tiers[Tier],"Gold",Customer_Tiers[Activity Status],"Inactive") -> 0
A37: Gold at Risk | B37: =COUNTIFS(Customer_Tiers[Tier],"Gold",Customer_Tiers[Activity Status],"At Risk") -> 0
A38: Top 100 Inactivity Count | B38: =COUNTIFS(Customer_Tiers[Rank],"<="&100,Customer_Tiers[Activity Status],"Inactive") -> 20
A44: B2B Revenue | B44: =B2BvsB2C!B4/B2BvsB2C!B6 -> 0.27932359
A45: B2C Revenue | B45: =B2BvsB2C!B5/B2BvsB2C!B6 -> 0.72067641

Sheet B2BvsB2C
A3: Vch Type | B3: Sum of Sales Amount
A4: B2B | B4: 15993222
A5: B2C | B5: 41263746
A6: Grand Total | B6: 57256968

Sheet Sales Register
A1: Date | B1: Customer_name | C1: Vch Type | D1: Vch No. | E1: Sales Amount | F1: Credit
A2: 45748 | B2: KERALA STEELS | C2: B2B | D2: JU-1/25-26 | E2: 7055
A3: 45748 | B3: SUNIL NJARALLOOR | C3: B2C | D3: J-1/25-26 | E3: 2380
A4: 45748 | B4: MANOJ (CURRY SHOP) | C4: B2C | D4: J-2/25-26 | E4: 680
A5: 45748 | B5: SHIJO AUTO CONSULTANT | C5: B2C | D5: J-3/25-26 | E5: 4776
A6: 45748 | B6: VASU SRISHITY | C6: B2C | D6: J-4/25-26 | E6: 2073
A7: 45748 | B7: JOBY THATTAMUGAL | C7: B2C | D7: J-5/25-26 | E7: 1300
A8: 45748 | B8: JAYAN KUNNAKKAL | C8: B2C | D8: J-6/25-26 | E8: 6800
A9: 45748 | B9: MOHANAN PANCODE | C9: B2C | D9: J-7/25-26 | E9: 30855
A10: 45748 | B10: BINU KOLETH TRUSS | C10: B2C | D10: J-8/25-26 | E10: 2218
A11: 45748 | B11: BHASKARAN PATTIMATTOM | C11: B2C | D11: J-9/25-26 | E11: 1329
A12: 45748 | B12: BINU KOLETH TRUSS | C12: B2C | D12: J-10/25-26 | E12: 748
A13: 45748 | B13: NIJU TRUSS , PATTIMATTAM | C13: B2C | D13: J-11/25-26 | E13: 19570
... A284: 45763 | B284: AUGUR COMPUTERS PVT LTD | C284: B2B | D284: JU-38/25-26 | E284: 10374
A285: 45763 | B285: (cancelled) | C285: B2B | D285: JU-39/25-26
A286: 45763 | B286: SAKKEER PLAPPILLY APE | C286: B2C | D286: J-246/25-26 | E286: 1050
A287: 45763 | B287: YOHANNAN MECHANGARA | C287: B2C | D287: J-247/25-26 | E287: 12637
A288: 45763 | B288: SUNIL KANDOTH | C288: B2C | D288: J-248/25-26 | E288: 20165
A289: 45763 | B289: ASHARAF VEGETABLE SHOP 1 | C289: B2C | D289: J-249/25-26 | E289: 7573
A290: 45763 | B290: SAJI , TRUSS KILIKULAM | C290: B2C | D290: J-250/25-26 | E290: 316
A291: 45763 | B291: SUNIL SEBASTIAN | C291: B2C | D291: J-251/25-26 | E291: 764
A292: 45763 | B292: Cash | C292: B2C | D292: J-252/25-26 | E292: 12
A293: 45763 | B293: JOHNSON NJARALLOOR | C293: B2C | D293: J-253/25-26 | E293: 350
A294: 45763 | B294: BINU KOLETH TRUSS | C294: B2C | D294: J-254/25-26 | E294: 734
A295: 45763 | B295: NAVAS THANDAKKALA (CATERING) | C295: B2C | D295: J-255/25-26 | E295: 100
A296: 45763 | B296: SABU MYLATTUMUGAL | C296: B2C | D296: J-256/25-26 | E296: 495
A297: 45763 | B297: NIJAS MUVATTUPUZHA | C297: B2C | D297: J-257/25-26 | E297: 7737
... A602: 45779 | B602: JAYAPRAKASH | C602: B2C | D602: J-527/25-26 | E602: 295776
A603: 45780 | B603: (cancelled) | C603: B2B | D603: JU-75/25-26
A604: 45780 | B604: KOTTARAM BUILDERS AND DEVELOPERS | C604: B2B | D604: JU-76/25-26 | E604: 13557
A605: 45780 | B605: FLAVOURFAVE (P) LTD | C605: B2B | D605: JU-77/25-26 | E605: 6270
A606: 45780 | B606: DAMODARAN NAMBOORI | C606: B2C | D606: J-528/25-26 | E606: 5400
A607: 45780 | B607: SURESH KUMAR P C | C607: B2C | D607: J-529/25-26 | E607: 1490
A608: 45780 | B608: ARUN A R | C608: B2C | D608: J-530/25-26 | E608: 16598
A609: 45780 | B609: CHANDRAN DOUBLE PALAM | C609: B2C | D609: J-531/25-26 | E609: 720
A610: 45780 | B610: HAMEED TRUSS | C610: B2C | D610: J-532/25-26 | E610: 6440
A611: 45780 | B611: Cash | C611: B2C | D611: J-533/25-26 | E611: 12
A612: 45780 | B612: RASHEED TRUSS , CHENGARA | C612: B2C | D612: J-534/25-26 | E612: 2220
A613: 45780 | B613: JOHNY WORKSHOP | C613: B2C | D613: J-535/25-26 | E613: 20890
A614: 45780 | B614: AJI TRUSS | C614: B2C | D614: J-536/25-26 | E614: 9734
...

Sheet MaxDate
A3: Customers | B3: LastPurchaseDate | C3: Sum of Sales Amount
A4: JAYAPRAKASH | B4: 46076 | C4: 1760156
A5: FLAVOURNEST PRIVATE LIMITED | B5: 46062 | C5: 1686991
A6: ST.ANTONY'S FORANE CHURCH | B6: 46002 | C6: 1625575
A7: DREEM DECOR COCHIN | B7: 46077 | C7: 1483378
A8: ABDUL SAMAD | B8: 46074 | C8: 1425127.9
A9: Cash | B9: 46080 | C9: 1279923
A10: VASU SRISHITY | B10: 46077 | C10: 1081054
A11: PARACKAL METAL CRUSHERS LLP | B11: 46081 | C11: 912480
A12: BINU KOLETH TRUSS | B12: 46079 | C12: 815695
A13: RASHEED TRUSS , CHENGARA | B13: 46080 | C13: 811009
A14: SIVASAKTHI CABLE TV NET WORK | B14: 46056 | C14: 721570
A15: NIJU TRUSS , PATTIMATTAM | B15: 46041 | C15: 648248
... A1428: AZEES CHELAKKULAM | B1428: 45988 | C1428: 10

Sheet Top Customers
A3: Customers | B3: Sales
A4: JAYAPRAKASH | B4: 1760156
A5: FLAVOURNEST PRIVATE LIMITED | B5: 1686991
A6: ST.ANTONY'S FORANE CHURCH | B6: 1625575
A7: DREEM DECOR COCHIN | B7: 1483378
A8: ABDUL SAMAD | B8: 1425127.9
A9: Cash | B9: 1279923
A10: VASU SRISHITY | B10: 1081054
A11: PARACKAL METAL CRUSHERS LLP | B11: 912480
A12: BINU KOLETH TRUSS | B12: 815695
A13: RASHEED TRUSS , CHENGARA | B13: 811009
A14: SIVASAKTHI CABLE TV NET WORK | B14: 721570
A15: NIJU TRUSS , PATTIMATTAM | B15: 648248
... A1428: AZEES CHELAKKULAM | B1428: 10

Sheet Tier vs Sale
A3: Tier | B3: Sum of Total_Sales
A4: Gold | B4: 5612534
A5: Platinum | B5: 10342205
A6: Regular | B6: 20159226
A7: Silver | B7: 21143003
A8: Grand Total | B8: 57256968

Sheet Tier vs Customer_Count
A3: Tier | B3: Customer_Count
A4: Gold | B4: 8
A5: Platinum | B5: 58
A6: Silver | B6: 105
A7: Grand Total | B7: 171

Sheet Customer_Tiers
A1: Customer | B1: Total_Sales | C1: Tier | D1: Gap to Next Tier | E1: Contribution | F1: Days Since Last Purchase | G1: Activity Status | H1: Rank | Q1: =GETPIVOTDATA("Sales Amount",'Top Customers'!$A$3,"Customer_name",'Top Customers'!A4) -> 1760156
A2: ='Top Customers'!A4 -> JAYAPRAKASH | B2: =IF(A2="","",IFERROR(GETPIVOTDATA("Sales Amount",'Top Customers'!$A$3,"Customer_name",'Top Customers'!A4),"")) -> 1760156 | C2: =IF(B2>=1000000,"Platinum", IF(B2>=500000,"Gold", IF(B2>=100000,"Silver","Regular"))) -> Platinum | D2: =IF(C2="Platinum",0, IF(C2="Gold",1000000-B2, IF(C2="Silver",500000-B2, IF(C2="Regular",100000-B2,0)))) -> 0 | E2: =B2/SUM(B:B) -> 0.030741341 | F2: =TODAY()-GETPIVOTDATA("LastPurchaseDate",MaxDate!$A$3,"Customer_name",MaxDate!A4) -> 6 | G2: =IF(F2="","", IF(F2<=60,"Active", IF(F2<=120,"At Risk","Inactive"))) -> Active | H2: =RANK(B2,Customer_Tiers[Total_Sales]) -> 1
A3: ='Top Customers'!A5 -> FLAVOURNEST PRIVATE LIMITED | B3: =IF(A3="","",IFERROR(GETPIVOTDATA("Sales Amount",'Top Customers'!$A$3,"Customer_name",'Top Customers'!A5),"")) -> 1686991 | C3: =IF(B3>=1000000,"Platinum", IF(B3>=500000,"Gold", IF(B3>=100000,"Silver","Regular"))) -> Platinum | D3: =IF(C3="Platinum",0, IF(C3="Gold",1000000-B3, IF(C3="Silver",500000-B3, IF(C3="Regular",100000-B3,0)))) -> 0 | E3: =B3/SUM(B:B) -> 0.029463506 | F3: =TODAY()-GETPIVOTDATA("LastPurchaseDate",MaxDate!$A$3,"Customer_name",MaxDate!A5) -> 20 | G3: =IF(F3="","", IF(F3<=60,"Active", IF(F3<=120,"At Risk","Inactive"))) -> Active | H3: =RANK(B3,Customer_Tiers[Total_Sales]) -> 2
A4: ='Top Customers'!A6 -> ST.ANTONY'S FORANE CHURCH | B4: =IF(A4="","",IFERROR(GETPIVOTDATA("Sales Amount",'Top Customers'!$A$3,"Customer_name",'Top Customers'!A6),"")) -> 1625575 | C4: =IF(B4>=1000000,"Platinum", IF(B4>=500000,"Gold", IF(B4>=100000,"Silver","Regular"))) -> Platinum | D4: =IF(C4="Platinum",0, IF(C4="Gold",1000000-B4, IF(C4="Silver",500000-B4, IF(C4="Regular",100000-B4,0)))) -> 0 | E4: =B4/SUM(B:B) -> 0.028390868 | F4: =TODAY()-GETPIVOTDATA("LastPurchaseDate",MaxDate!$A$3,"Customer_name",MaxDate!A6) -> 80 | G4: =IF(F4="","", IF(F4<=60,"Active", IF(F4<=120,"At Risk","Inactive"))) -> At Risk | H4: =RANK(B4,Customer_Tiers[Total_Sales]) -> 3
A5: ='Top Customers'!A7 -> DREEM DECOR COCHIN | B5: =IF(A5="","",IFERROR(GETPIVOTDATA("Sales Amount",'Top Customers'!$A$3,"Customer_name",'Top Customers'!A7),"")) -> 1483378 | C5: =IF(B5>=1000000,"Platinum", IF(B5>=500000,"Gold", IF(B5>=100000,"Silver","Regular"))) -> Platinum | D5: =IF(C5="Platinum",0, IF(C5="Gold",1000000-B5, IF(C5="Silver",500000-B5, IF(C5="Regular",100000-B5,0)))) -> 0 | E5: =B5/SUM(B:B) -> 0.02590738 | F5: =TODAY()-GETPIVOTDATA("LastPurchaseDate",MaxDate!$A$3,"Customer_name",MaxDate!A7) -> 5 | G5: =IF(F5="","", IF(F5<=60,"Active", IF(F5<=120,"At Risk","Inactive"))) -> Active | H5: =RANK(B5,Customer_Tiers[Total_Sales]) -> 4
A6: ='Top Customers'!A8 -> ABDUL SAMAD | B6: =IF(A6="","",IFERROR(GETPIVOTDATA("Sales Amount",'Top Customers'!$A$3,"Customer_name",'Top Customers'!A8),"")) -> 1425127.9 | C6: =IF(B6>=1000000,"Platinum", IF(B6>=500000,"Gold", IF(B6>=100000,"Silver","Regular"))) -> Platinum | D6: =IF(C6="Platinum",0, IF(C6="Gold",1000000-B6, IF(C6="Silver",500000-B6, IF(C6="Regular",100000-B6,0)))) -> 0 | E6: =B6/SUM(B:B) -> 0.024890035 | F6: =TODAY()-GETPIVOTDATA("LastPurchaseDate",MaxDate!$A$3,"Customer_name",MaxDate!A8) -> 8 | G6: =IF(F6="","", IF(F6<=60,"Active", IF(F6<=120,"At Risk","Inactive"))) -> Active | H6: =RANK(B6,Customer_Tiers[Total_Sales]) -> 5
A7: ='Top Customers'!A9 -> Cash | B7: =IF(A7="","",IFERROR(GETPIVOTDATA("Sales Amount",'Top Customers'!$A$3,"Customer_name",'Top Customers'!A9),"")) -> 1279923 | C7: =IF(B7>=1000000,"Platinum", IF(B7>=500000,"Gold", IF(B7>=100000,"Silver","Regular"))) -> Platinum | D7: =IF(C7="Platinum",0, IF(C7="Gold",1000000-B7, IF(C7="Silver",500000-B7, IF(C7="Regular",100000-B7,0)))) -> 0 | E7: =B7/SUM(B:B) -> 0.022354013 | F7: =TODAY()-GETPIVOTDATA("LastPurchaseDate",MaxDate!$A$3,"Customer_name",MaxDate!A9) -> 2 | G7: =IF(F7="","", IF(F7<=60,"Active", IF(F7<=120,"At Risk","Inactive"))) -> Active | H7: =RANK(B7,Customer_Tiers[Total_Sales]) -> 6
A8: ='Top Customers'!A10 -> VASU SRISHITY | B8: =IF(A8="","",IFERROR(GETPIVOTDATA("Sales Amount",'Top Customers'!$A$3,"Customer_name",'Top Customers'!A10),"")) -> 1081054 | C8: =IF(B8>=1000000,"Platinum", IF(B8>=500000,"Gold", IF(B8>=100000,"Silver","Regular"))) -> Platinum | D8: =IF(C8="Platinum",0, IF(C8="Gold",1000000-B8, IF(C8="Silver",500000-B8, IF(C8="Regular",100000-B8,0)))) -> 0 | E8: =B8/SUM(B:B) -> 0.018880741 | F8: =TODAY()-GETPIVOTDATA("LastPurchaseDate",MaxDate!$A$3,"Customer_name",MaxDate!A10) -> 5 | G8: =IF(F8="","", IF(F8<=60,"Active", IF(F8<=120,"At Risk","Inactive"))) -> Active | H8: =RANK(B8,Customer_Tiers[Total_Sales]) -> 7
A9: ='Top Customers'!A11 -> PARACKAL METAL CRUSHERS LLP | B9: =IF(A9="","",IFERROR(GETPIVOTDATA("Sales Amount",'Top Customers'!$A$3,"Customer_name",'Top Customers'!A11),"")) -> 912480 | C9: =IF(B9>=1000000,"Platinum", IF(B9>=500000,"Gold", IF(B9>=100000,"Silver","Regular"))) -> Gold | D9: =IF(C9="Platinum",0, IF(C9="Gold",1000000-B9, IF(C9="Silver",500000-B9, IF(C9="Regular",100000-B9,0)))) -> 87520 | E9: =B9/SUM(B:B) -> 0.015936576 | F9: =TODAY()-GETPIVOTDATA("LastPurchaseDate",MaxDate!$A$3,"Customer_name",MaxDate!A11) -> 1 | G9: =IF(F9="","", IF(F9<=60,"Active", IF(F9<=120,"At Risk","Inactive"))) -> Active | H9: =RANK(B9,Customer_Tiers[Total_Sales]) -> 8
A10: ='Top Customers'!A12 -> BINU KOLETH TRUSS | B10: =IF(A10="","",IFERROR(GETPIVOTDATA("Sales Amount",'Top Customers'!$A$3,"Customer_name",'Top Customers'!A12),"")) -> 815695 | C10: =IF(B10>=1000000,"Platinum", IF(B10>=500000,"Gold", IF(B10>=100000,"Silver","Regular"))) -> Gold | D10: =IF(C10="Platinum",0, IF(C10="Gold",1000000-B10, IF(C10="Silver",500000-B10, IF(C10="Regular",100000-B10,0)))) -> 184305 | E10: =B10/SUM(B:B) -> 0.014246214 | F10: =TODAY()-GETPIVOTDATA("LastPurchaseDate",MaxDate!$A$3,"Customer_name",MaxDate!A12) -> 3 | G10: =IF(F10="","", IF(F10<=60,"Active", IF(F10<=120,"At Risk","Inactive"))) -> Active | H10: =RANK(B10,Customer_Tiers[Total_Sales]) -> 9
A11: ='Top Customers'!A13 -> RASHEED TRUSS , CHENGARA | B11: =IF(A11="","",IFERROR(GETPIVOTDATA("Sales Amount",'Top Customers'!$A$3,"Customer_name",'Top Customers'!A13),"")) -> 811009 | C11: =IF(B11>=1000000,"Platinum", IF(B11>=500000,"Gold", IF(B11>=100000,"Silver","Regular"))) -> Gold | D11: =IF(C11="Platinum",0, IF(C11="Gold",1000000-B11, IF(C11="Silver",500000-B11, IF(C11="Regular",100000-B11,0)))) -> 188991 | E11: =B11/SUM(B:B) -> 0.014164372 | F11: =TODAY()-GETPIVOTDATA("LastPurchaseDate",MaxDate!$A$3,"Customer_name",MaxDate!A13) -> 2 | G11: =IF(F11="","", IF(F11<=60,"Active", IF(F11<=120,"At Risk","Inactive"))) -> Active | H11: =RANK(B11,Customer_Tiers[Total_Sales]) -> 10
A12: ='Top Customers'!A14 -> SIVASAKTHI CABLE TV NET WORK | B12: =IF(A12="","",IFERROR(GETPIVOTDATA("Sales Amount",'Top Customers'!$A$3,"Customer_name",'Top Customers'!A14),"")) -> 721570 | C12: =IF(B12>=1000000,"Platinum", IF(B12>=500000,"Gold", IF(B12>=100000,"Silver","Regular"))) -> Gold | D12: =IF(C12="Platinum",0, IF(C12="Gold",1000000-B12, IF(C12="Silver",500000-B12, IF(C12="Regular",100000-B12,0)))) -> 278430 | E12: =B12/SUM(B:B) -> 0.012602309 | F12: =TODAY()-GETPIVOTDATA("LastPurchaseDate",MaxDate!$A$3,"Customer_name",MaxDate!A14) -> 26 | G12: =IF(F12="","", IF(F12<=60,"Active", IF(F12<=120,"At Risk","Inactive"))) -> Active | H12: =RANK(B12,Customer_Tiers[Total_Sales]) -> 11
A13: ='Top Customers'!A15 -> NIJU TRUSS , PATTIMATTAM | B13: =IF(A13="","",IFERROR(GETPIVOTDATA("Sales Amount",'Top Customers'!$A$3,"Customer_name",'Top Customers'!A15),"")) -> 648248 | C13: =IF(B13>=1000000,"Platinum", IF(B13>=500000,"Gold", IF(B13>=100000,"Silver","Regular"))) -> Gold | D13: =IF(C13="Platinum",0, IF(C13="Gold",1000000-B13, IF(C13="Silver",500000-B13, IF(C13="Regular",100000-B13,0)))) -> 351752 | E13: =B13/SUM(B:B) -> 0.011321731 | F13: =TODAY()-GETPIVOTDATA("LastPurchaseDate",MaxDate!$A$3,"Customer_name",MaxDate!A15) -> 41 | G13: =IF(F13="","", IF(F13<=60,"Active", IF(F13<=120,"At Risk","Inactive"))) -> Active | H13: =RANK(B13,Customer_Tiers[Total_Sales]) -> 12
... A1477: ='Top Customers'!A1479 -> 0 | B1477: =IF(A1477="","",IFERROR(GETPIVOTDATA("Sales Amount",'Top Customers'!$A$3,"Customer_name",'Top Customers'!A1479),"")) | C1477: =IF(B1477>=1000000,"Platinum", IF(B1477>=500000,"Gold", IF(B1477>=100000,"Silver","Regular"))) -> Platinum | D1477: =IF(C1477="Platinum",0, IF(C1477="Gold",1000000-B1477, IF(C1477="Silver",500000-B1477, IF(C1477="Regular",100000-B1477,0)))) -> 0 | E1477: =B1477/SUM(B:B) -> #VALUE! | F1477: =TODAY()-GETPIVOTDATA("LastPurchaseDate",MaxDate!$A$3,"Customer_name",MaxDate!A1479) -> #REF! | G1477: =IF(F1477="","", IF(F1477<=60,"Active", IF(F1477<=120,"At Risk","Inactive"))) -> #REF! | H1477: =RANK(B1477,Customer_Tiers[Total_Sales]) -> #VALUE!
